Workbook

Sheet 00_Cover
B2: Northline Consumer Products
B3: Monthly KPI scorecard · ops + finance · actual vs target with RAG
B4: FY2026 monthly · 12 KPIs · fictional CPG company
B6: What this file is
B7: A twelve-month operating and finance scorecard for a fictional mid-size CPG company. Targets and RAG thresholds live on Assumptions; monthly actuals are inputs; the scorecard, YTD, trends, and dashboard are formulas (Green / Amber / Red).
B9: How to use
B10: 1. Edit yellow cells on 01_Assumptions (KPI targets, direction H/L/R, amber/green bands, reporting month).
B11: 2. Paste or type monthly actuals on 02_Actuals (yellow).
B12: 3. Read actual vs target, variance, and RAG on 03_Scorecard — nothing on that tab is hardcoded.
B13: 4. Read MoM, rolling 3-month, YTD, and vs-target trends on 04_Trends.
B14: 5. Use 05_Dashboard as the one-pager (traffic-light tiles + charts).
B16: File conventions
... B23: https://github.com/saisiri-bandaru

Sheet 01_Assumptions
B2: Assumptions
B3: Yellow + blue = inputs. Targets, direction, and RAG bands drive the scorecard.
B5: Reporting month (1 = Jan-26 … 12 = Dec-26) | C5: 9 | D5: =INDEX({"Jan-26","Feb-26","Mar-26","Apr-26","May-26","Jun-26","Jul-26","Aug-26","Sep-26","Oct-26","Nov-26","Dec-26"},1,C5) | E5: Scorecard as-of and dashboard INDEX to this month. Sample is parked in Sep so YTD is visible.
B7: RAG rules
B8: H (higher-better): Green if actual ≥ target; Amber if actual ≥ target × (1 − amber band); else Red.
B9: L (lower-better): Green if actual ≤ target; Amber if actual ≤ target × (1 + amber band); else Red.
B10: R (range, e.g. headcount): Green if |actual/target − 1| ≤ green band; Amber if ≤ amber band; else Red.
B12: KPI register
B13: KPI | C13: Unit | D13: Direction (H/L/R) | E13: Amber band | F13: Green band (R) | G13: Aggregation | H13: Polarity
B14: Net revenue | C14: $000s | D14: H | E14: 0.03 | F14: 0.02 | G14: SUM | H14: Higher is better
B15: Gross margin % | C15: % | D15: H | E15: 0.015 | F15: 0.008 | G15: AVG | H15: Higher is better
B16: EBITDA | C16: $000s | D16: H | E16: 0.05 | F16: 0.02 | G16: SUM | H16: Higher is better
B17: Volume | C17: 000 cases | D17: H | E17: 0.03 | F17: 0.02 | G17: SUM | H17: Higher is better
B18: OTIF % | C18: % | D18: H | E18: 0.02 | F18: 0.01 | G18: AVG | H18: Higher is better
B19: Scrap % | C19: % | D19: L | E19: 0.15 | F19: 0.05 | G19: AVG | H19: Lower is better
B20: DSO | C20: days | D20: L | E20: 0.08 | F20: 0.03 | G20: LAST | H20: Lower is better
B21: CCC | C21: days | D21: L | E21: 0.08 | F21: 0.03 | G21: LAST | H21: Lower is better
B22: Headcount | C22: FTE | D22: R | E22: 0.03 | F22: 0.015 | G22: LAST | H22: Hit the plan (range)
B23: Attrition % (ann.) | C23: % | D23: L | E23: 0.15 | F23: 0.05 | G23: AVG | H23: Lower is better
B24: Operating cash flow | C24: $000s | D24: H | E24: 0.1 | F24: 0.04 | G24: SUM | H24: Higher is better
B25: SG&A % of sales | C25: % | D25: L | E25: 0.04 | F25: 0.015 | G25: AVG | H25: Lower is better
B27: Monthly targets — FY2026 (inputs)
C28: Jan-26 | D28: Feb-26 | E28: Mar-26 | F28: Apr-26 | G28: May-26 | H28: Jun-26 | I28: Jul-26 | J28: Aug-26 | K28: Sep-26 | L28: Oct-26 | M28: Nov-26 | N28: Dec-26 | O28: FY26
B29: Net revenue | C29: 71000 | D29: 68000 | E29: 73500 | F29: 75000 | G29: 77500 | H29: 79000 | I29: 80500 | J29: 79800 | K29: 77200 | L29: 82000 | M29: 87500 | N29: 94000 | O29: =SUM(C29:N29)
B30: Gross margin % | C30: 0.422 | D30: 0.422 | E30: 0.424 | F30: 0.425 | G30: 0.426 | H30: 0.427 | I30: 0.427 | J30: 0.426 | K30: 0.425 | L30: 0.428 | M30: 0.43 | N30: 0.432 | O30: =AVERAGE(C30:N30)
B31: EBITDA | C31: 10295 | D31: 9860 | E31: 10658 | F31: 10875 | G31: 11238 | H31: 11455 | I31: 11672 | J31: 11571 | K31: 11194 | L31: 11890 | M31: 12688 | N31: 13630 | O31: =SUM(C31:N31)
B32: Volume | C32: 5917 | D32: 5667 | E32: 6125 | F32: 6250 | G32: 6458 | H32: 6583 | I32: 6708 | J32: 6650 | K32: 6433 | L32: 6833 | M32: 7292 | N32: 7833 | O32: =SUM(C32:N32)
B33: OTIF % | C33: 0.97 | D33: 0.97 | E33: 0.97 | F33: 0.97 | G33: 0.97 | H33: 0.97 | I33: 0.97 | J33: 0.97 | K33: 0.97 | L33: 0.97 | M33: 0.97 | N33: 0.97 | O33: =AVERAGE(C33:N33)
B34: Scrap % | C34: 0.018 | D34: 0.018 | E34: 0.018 | F34: 0.018 | G34: 0.018 | H34: 0.018 | I34: 0.018 | J34: 0.018 | K34: 0.018 | L34: 0.018 | M34: 0.018 | N34: 0.018 | O34: =AVERAGE(C34:N34)
B35: DSO | C35: 42 | D35: 42 | E35: 42 | F35: 42 | G35: 42 | H35: 42 | I35: 42 | J35: 42 | K35: 42 | L35: 42 | M35: 42 | N35: 42 | O35: =N35
B36: CCC | C36: 62 | D36: 62 | E36: 62 | F36: 62 | G36: 62 | H36: 62 | I36: 62 | J36: 62 | K36: 62 | L36: 62 | M36: 62 | N36: 62 | O36: =N36
B37: Headcount | C37: 286.5 | D37: 287.8 | E37: 289.2 | F37: 291 | G37: 292.4 | H37: 294.1 | I37: 297 | J37: 298.4 | K37: 299.1 | L37: 302.3 | M37: 303.5 | N37: 304.8 | O37: =N37
B38: Attrition % (ann.) | C38: 0.12 | D38: 0.12 | E38: 0.12 | F38: 0.12 | G38: 0.12 | H38: 0.12 | I38: 0.12 | J38: 0.12 | K38: 0.12 | L38: 0.12 | M38: 0.12 | N38: 0.12 | O38: =AVERAGE(C38:N38)
B39: Operating cash flow | C39: 5680 | D39: 5440 | E39: 5880 | F39: 6000 | G39: 6200 | H39: 6320 | I39: 6440 | J39: 6384 | K39: 6176 | L39: 6560 | M39: 7000 | N39: 7520 | O39: =SUM(C39:N39)
B40: SG&A % of sales | C40: 0.185 | D40: 0.185 | E40: 0.185 | F40: 0.185 | G40: 0.185 | H40: 0.185 | I40: 0.185 | J40: 0.185 | K40: 0.185 | L40: 0.185 | M40: 0.185 | N40: 0.185 | O40: =AVERAGE(C40:N40)
B42: FY25 actuals (for YoY on Trends) — revenue and volume only
C43: Jan-26 | D43: Feb-26 | E43: Mar-26 | F43: Apr-26 | G43: May-26 | H43: Jun-26 | I43: Jul-26 | J43: Aug-26 | K43: Sep-26 | L43: Oct-26 | M43: Nov-26 | N43: Dec-26 | O43: FY25
B44: Net revenue FY25 | C44: 66000 | D44: 64000 | E44: 69000 | F44: 70500 | G44: 72000 | H44: 73500 | I44: 75000 | J44: 74200 | K44: 72800 | L44: 76000 | M44: 80500 | N44: 87000 | O44: =SUM(C44:N44)
B45: Volume FY25 | C45: 5500 | D45: 5333 | E45: 5750 | F45: 5875 | G45: 6000 | H45: 6125 | I45: 6250 | J45: 6183 | K45: 6067 | L45: 6333 | M45: 6708 | N45: 7250 | O45: =SUM(C45:N45)
B47: Aggregation: SUM for flow KPIs (revenue, EBITDA, volume, cash). AVG for rates. LAST for stocks (DSO, CCC, headcount).

Sheet 02_Actuals
B2: Monthly actuals — FY2026
B3: Yellow + blue = inputs. Paste a new month here; scorecard, trends, and dashboard recalculate.
B5: Actuals
C6: Jan-26 | D6: Feb-26 | E6: Mar-26 | F6: Apr-26 | G6: May-26 | H6: Jun-26 | I6: Jul-26 | J6: Aug-26 | K6: Sep-26 | L6: Oct-26 | M6: Nov-26 | N6: Dec-26 | O6: FY26
B7: Net revenue | C7: 70200 | D7: 67400 | E7: 74100 | F7: 73800 | G7: 78200 | H7: 80100 | I7: 79800 | J7: 80500 | K7: 76500 | L7: 83400 | M7: 89200 | N7: 95800 | O7: =SUM(C7:N7)
B8: Gross margin % | C8: 0.418 | D8: 0.415 | E8: 0.422 | F8: 0.425 | G8: 0.428 | H8: 0.43 | I8: 0.427 | J8: 0.424 | K8: 0.421 | L8: 0.426 | M8: 0.432 | N8: 0.435 | O8: =AVERAGE(C8:N8)
B9: EBITDA | C9: 9688 | D9: 9166 | E9: 10670 | F9: 10849 | G9: 11652 | H9: 12095 | I9: 11651 | J9: 11511 | K9: 10786 | L9: 12343 | M9: 13558 | N9: 14753 | O9: =SUM(C9:N9)
B10: Volume | C10: 5792 | D10: 5532 | E10: 6237 | F10: 6027 | G10: 6614 | H10: 6808 | I10: 6584 | J10: 6775 | K10: 6279 | L10: 7089 | M10: 7619 | N10: 8223 | O10: =SUM(C10:N10)
B11: OTIF % | C11: 0.962 | D11: 0.951 | E11: 0.974 | F11: 0.978 | G11: 0.969 | H11: 0.975 | I11: 0.948 | J11: 0.961 | K11: 0.97 | L11: 0.976 | M11: 0.981 | N11: 0.964 | O11: =AVERAGE(C11:N11)
B12: Scrap % | C12: 0.021 | D12: 0.024 | E12: 0.019 | F12: 0.017 | G12: 0.018 | H12: 0.016 | I12: 0.022 | J12: 0.02 | K12: 0.019 | L12: 0.017 | M12: 0.015 | N12: 0.016 | O12: =AVERAGE(C12:N12)
B13: DSO | C13: 44.2 | D13: 45.1 | E13: 43.6 | F13: 42.9 | G13: 41.4 | H13: 42.1 | I13: 43 | J13: 44.2 | K13: 42.5 | L13: 41.2 | M13: 40 | N13: 41.6 | O13: =N13
B14: CCC | C14: 68.5 | D14: 69.3 | E14: 64.9 | F14: 62 | G14: 58.6 | H14: 59.9 | I14: 62.6 | J14: 65.2 | K14: 63.3 | L14: 58 | M14: 52.6 | N14: 54.6 | O14: =N14
B15: Headcount | C15: 286.5 | D15: 285.9 | E15: 288.4 | F15: 289.6 | G15: 291.8 | H15: 292.5 | I15: 295.6 | J15: 296.8 | K15: 297.9 | L15: 300.7 | M15: 302.8 | N15: 304.1 | O15: =N15
B16: Attrition % (ann.) | C16: 0.118 | D16: 0.152 | E16: 0.109 | F16: 0.101 | G16: 0.097 | H16: 0.141 | I16: 0.112 | J16: 0.134 | K16: 0.108 | L16: 0.099 | M16: 0.095 | N16: 0.102 | O16: =AVERAGE(C16:N16)
B17: Operating cash flow | C17: 5100 | D17: 4200 | E17: 6800 | F17: 5900 | G17: 7400 | H17: 7100 | I17: 5600 | J17: 6200 | K17: 4800 | L17: 7900 | M17: 9100 | N17: 8600 | O17: =SUM(C17:N17)
B18: SG&A % of sales | C18: 0.191 | D18: 0.194 | E18: 0.186 | F18: 0.184 | G18: 0.181 | H18: 0.179 | I18: 0.188 | J18: 0.187 | K18: 0.19 | L18: 0.182 | M18: 0.178 | N18: 0.176 | O18: =AVERAGE(C18:N18)
B20: YTD (through reporting month) — formulas
B21: KPI | C21: YTD actual | D21: YTD target | E21: YTD var | F21: Aggregation
B22: Net revenue | C22: =SUM(OFFSET(C7,0,0,1,'01_Assumptions'!$C$5)) | D22: =SUM(OFFSET('01_Assumptions'!C29,0,0,1,'01_Assumptions'!$C$5)) | E22: =C22-D22 | F22: SUM
B23: Gross margin % | C23: =AVERAGE(OFFSET(C8,0,0,1,'01_Assumptions'!$C$5)) | D23: =AVERAGE(OFFSET('01_Assumptions'!C30,0,0,1,'01_Assumptions'!$C$5)) | E23: =C23-D23 | F23: AVG
B24: EBITDA | C24: =SUM(OFFSET(C9,0,0,1,'01_Assumptions'!$C$5)) | D24: =SUM(OFFSET('01_Assumptions'!C31,0,0,1,'01_Assumptions'!$C$5)) | E24: =C24-D24 | F24: SUM
B25: Volume | C25: =SUM(OFFSET(C10,0,0,1,'01_Assumptions'!$C$5)) | D25: =SUM(OFFSET('01_Assumptions'!C32,0,0,1,'01_Assumptions'!$C$5)) | E25: =C25-D25 | F25: SUM
B26: OTIF % | C26: =AVERAGE(OFFSET(C11,0,0,1,'01_Assumptions'!$C$5)) | D26: =AVERAGE(OFFSET('01_Assumptions'!C33,0,0,1,'01_Assumptions'!$C$5)) | E26: =C26-D26 | F26: AVG
B27: Scrap % | C27: =AVERAGE(OFFSET(C12,0,0,1,'01_Assumptions'!$C$5)) | D27: =AVERAGE(OFFSET('01_Assumptions'!C34,0,0,1,'01_Assumptions'!$C$5)) | E27: =C27-D27 | F27: AVG
B28: DSO | C28: =INDEX(C13:N13,1,'01_Assumptions'!$C$5) | D28: =INDEX('01_Assumptions'!C35:N35,1,'01_Assumptions'!$C$5) | E28: =C28-D28 | F28: LAST
B29: CCC | C29: =INDEX(C14:N14,1,'01_Assumptions'!$C$5) | D29: =INDEX('01_Assumptions'!C36:N36,1,'01_Assumptions'!$C$5) | E29: =C29-D29 | F29: LAST
B30: Headcount | C30: =INDEX(C15:N15,1,'01_Assumptions'!$C$5) | D30: =INDEX('01_Assumptions'!C37:N37,1,'01_Assumptions'!$C$5) | E30: =C30-D30 | F30: LAST
B31: Attrition % (ann.) | C31: =AVERAGE(OFFSET(C16,0,0,1,'01_Assumptions'!$C$5)) | D31: =AVERAGE(OFFSET('01_Assumptions'!C38,0,0,1,'01_Assumptions'!$C$5)) | E31: =C31-D31 | F31: AVG
B32: Operating cash flow | C32: =SUM(OFFSET(C17,0,0,1,'01_Assumptions'!$C$5)) | D32: =SUM(OFFSET('01_Assumptions'!C39,0,0,1,'01_Assumptions'!$C$5)) | E32: =C32-D32 | F32: SUM
B33: SG&A % of sales | C33: =AVERAGE(OFFSET(C18,0,0,1,'01_Assumptions'!$C$5)) | D33: =AVERAGE(OFFSET('01_Assumptions'!C40,0,0,1,'01_Assumptions'!$C$5)) | E33: =C33-D33 | F33: AVG
B35: OFFSET/INDEX YTD respects the reporting month on Assumptions. LAST KPIs use the as-of month, not a sum.

Sheet 03_Scorecard
B2: Scorecard — actual vs target and RAG
B3: Every value on this sheet is a formula. RAG uses the H / L / R rules and bands on Assumptions.
B4: As-of month | C4: ='01_Assumptions'!D5
B6: As-of month scorecard
B7: KPI | C7: Actual | D7: Target | E7: Var | F7: Var % | G7: RAG | H7: YTD actual | I7: YTD target | J7: YTD var | K7: YTD RAG
B8: ='01_Assumptions'!B14 | C8: =INDEX('02_Actuals'!C7:N7,1,'01_Assumptions'!$C$5) | D8: =INDEX('01_Assumptions'!C29:N29,1,'01_Assumptions'!$C$5) | E8: =C8-D8 | F8: =IF(D8=0,"—",C8/D8-1) | G8: =IF(D8=0,"—",IF('01_Assumptions'!$D$14="H",IF(C8>=D8,"Green",IF(C8>=D8*(1-'01_Assumptions'!$E$14),"Amber","Red")),IF('01_Assumptions'!$D$14="L",IF(C8<=D8,"Green",IF(C8<=D8*(1+'01_Assumptions'!$E$14),"Amber","Red")),IF(ABS(C8/D8-1)<='01_Assumptions'!$F$14,"Green",IF(ABS(C8/D8-1)<='01_Assumptions'!$E$14,"Amber","Red"))))) | H8: ='02_Actuals'!C22 | I8: ='02_Actuals'!D22 | J8: =H8-I8 | K8: =IF(I8=0,"—",IF('01_Assumptions'!$D$14="H",IF(H8>=I8,"Green",IF(H8>=I8*(1-'01_Assumptions'!$E$14),"Amber","Red")),IF('01_Assumptions'!$D$14="L",IF(H8<=I8,"Green",IF(H8<=I8*(1+'01_Assumptions'!$E$14),"Amber","Red")),IF(ABS(H8/I8-1)<='01_Assumptions'!$F$14,"Green",IF(ABS(H8/I8-1)<='01_Assumptions'!$E$14,"Amber","Red")))))
B9: ='01_Assumptions'!B15 | C9: =INDEX('02_Actuals'!C8:N8,1,'01_Assumptions'!$C$5) | D9: =INDEX('01_Assumptions'!C30:N30,1,'01_Assumptions'!$C$5) | E9: =C9-D9 | F9: =IF(D9=0,"—",C9/D9-1) | G9: =IF(D9=0,"—",IF('01_Assumptions'!$D$15="H",IF(C9>=D9,"Green",IF(C9>=D9*(1-'01_Assumptions'!$E$15),"Amber","Red")),IF('01_Assumptions'!$D$15="L",IF(C9<=D9,"Green",IF(C9<=D9*(1+'01_Assumptions'!$E$15),"Amber","Red")),IF(ABS(C9/D9-1)<='01_Assumptions'!$F$15,"Green",IF(ABS(C9/D9-1)<='01_Assumptions'!$E$15,"Amber","Red"))))) | H9: ='02_Actuals'!C23 | I9: ='02_Actuals'!D23 | J9: =H9-I9 | K9: =IF(I9=0,"—",IF('01_Assumptions'!$D$15="H",IF(H9>=I9,"Green",IF(H9>=I9*(1-'01_Assumptions'!$E$15),"Amber","Red")),IF('01_Assumptions'!$D$15="L",IF(H9<=I9,"Green",IF(H9<=I9*(1+'01_Assumptions'!$E$15),"Amber","Red")),IF(ABS(H9/I9-1)<='01_Assumptions'!$F$15,"Green",IF(ABS(H9/I9-1)<='01_Assumptions'!$E$15,"Amber","Red")))))
B10: ='01_Assumptions'!B16 | C10: =INDEX('02_Actuals'!C9:N9,1,'01_Assumptions'!$C$5) | D10: =INDEX('01_Assumptions'!C31:N31,1,'01_Assumptions'!$C$5) | E10: =C10-D10 | F10: =IF(D10=0,"—",C10/D10-1) | G10: =IF(D10=0,"—",IF('01_Assumptions'!$D$16="H",IF(C10>=D10,"Green",IF(C10>=D10*(1-'01_Assumptions'!$E$16),"Amber","Red")),IF('01_Assumptions'!$D$16="L",IF(C10<=D10,"Green",IF(C10<=D10*(1+'01_Assumptions'!$E$16),"Amber","Red")),IF(ABS(C10/D10-1)<='01_Assumptions'!$F$16,"Green",IF(ABS(C10/D10-1)<='01_Assumptions'!$E$16,"Amber","Red"))))) | H10: ='02_Actuals'!C24 | I10: ='02_Actuals'!D24 | J10: =H10-I10 | K10: =IF(I10=0,"—",IF('01_Assumptions'!$D$16="H",IF(H10>=I10,"Green",IF(H10>=I10*(1-'01_Assumptions'!$E$16),"Amber","Red")),IF('01_Assumptions'!$D$16="L",IF(H10<=I10,"Green",IF(H10<=I10*(1+'01_Assumptions'!$E$16),"Amber","Red")),IF(ABS(H10/I10-1)<='01_Assumptions'!$F$16,"Green",IF(ABS(H10/I10-1)<='01_Assumptions'!$E$16,"Amber","Red")))))
B11: ='01_Assumptions'!B17 | C11: =INDEX('02_Actuals'!C10:N10,1,'01_Assumptions'!$C$5) | D11: =INDEX('01_Assumptions'!C32:N32,1,'01_Assumptions'!$C$5) | E11: =C11-D11 | F11: =IF(D11=0,"—",C11/D11-1) | G11: =IF(D11=0,"—",IF('01_Assumptions'!$D$17="H",IF(C11>=D11,"Green",IF(C11>=D11*(1-'01_Assumptions'!$E$17),"Amber","Red")),IF('01_Assumptions'!$D$17="L",IF(C11<=D11,"Green",IF(C11<=D11*(1+'01_Assumptions'!$E$17),"Amber","Red")),IF(ABS(C11/D11-1)<='01_Assumptions'!$F$17,"Green",IF(ABS(C11/D11-1)<='01_Assumptions'!$E$17,"Amber","Red"))))) | H11: ='02_Actuals'!C25 | I11: ='02_Actuals'!D25 | J11: =H11-I11 | K11: =IF(I11=0,"—",IF('01_Assumptions'!$D$17="H",IF(H11>=I11,"Green",IF(H11>=I11*(1-'01_Assumptions'!$E$17),"Amber","Red")),IF('01_Assumptions'!$D$17="L",IF(H11<=I11,"Green",IF(H11<=I11*(1+'01_Assumptions'!$E$17),"Amber","Red")),IF(ABS(H11/I11-1)<='01_Assumptions'!$F$17,"Green",IF(ABS(H11/I11-1)<='01_Assumptions'!$E$17,"Amber","Red")))))
B12: ='01_Assumptions'!B18 | C12: =INDEX('02_Actuals'!C11:N11,1,'01_Assumptions'!$C$5) | D12: =INDEX('01_Assumptions'!C33:N33,1,'01_Assumptions'!$C$5) | E12: =C12-D12 | F12: =IF(D12=0,"—",C12/D12-1) | G12: =IF(D12=0,"—",IF('01_Assumptions'!$D$18="H",IF(C12>=D12,"Green",IF(C12>=D12*(1-'01_Assumptions'!$E$18),"Amber","Red")),IF('01_Assumptions'!$D$18="L",IF(C12<=D12,"Green",IF(C12<=D12*(1+'01_Assumptions'!$E$18),"Amber","Red")),IF(ABS(C12/D12-1)<='01_Assumptions'!$F$18,"Green",IF(ABS(C12/D12-1)<='01_Assumptions'!$E$18,"Amber","Red"))))) | H12: ='02_Actuals'!C26 | I12: ='02_Actuals'!D26 | J12: =H12-I12 | K12: =IF(I12=0,"—",IF('01_Assumptions'!$D$18="H",IF(H12>=I12,"Green",IF(H12>=I12*(1-'01_Assumptions'!$E$18),"Amber","Red")),IF('01_Assumptions'!$D$18="L",IF(H12<=I12,"Green",IF(H12<=I12*(1+'01_Assumptions'!$E$18),"Amber","Red")),IF(ABS(H12/I12-1)<='01_Assumptions'!$F$18,"Green",IF(ABS(H12/I12-1)<='01_Assumptions'!$E$18,"Amber","Red")))))
B13: ='01_Assumptions'!B19 | C13: =INDEX('02_Actuals'!C12:N12,1,'01_Assumptions'!$C$5) | D13: =INDEX('01_Assumptions'!C34:N34,1,'01_Assumptions'!$C$5) | E13: =C13-D13 | F13: =IF(D13=0,"—",C13/D13-1) | G13: =IF(D13=0,"—",IF('01_Assumptions'!$D$19="H",IF(C13>=D13,"Green",IF(C13>=D13*(1-'01_Assumptions'!$E$19),"Amber","Red")),IF('01_Assumptions'!$D$19="L",IF(C13<=D13,"Green",IF(C13<=D13*(1+'01_Assumptions'!$E$19),"Amber","Red")),IF(ABS(C13/D13-1)<='01_Assumptions'!$F$19,"Green",IF(ABS(C13/D13-1)<='01_Assumptions'!$E$19,"Amber","Red"))))) | H13: ='02_Actuals'!C27 | I13: ='02_Actuals'!D27 | J13: =H13-I13 | K13: =IF(I13=0,"—",IF('01_Assumptions'!$D$19="H",IF(H13>=I13,"Green",IF(H13>=I13*(1-'01_Assumptions'!$E$19),"Amber","Red")),IF('01_Assumptions'!$D$19="L",IF(H13<=I13,"Green",IF(H13<=I13*(1+'01_Assumptions'!$E$19),"Amber","Red")),IF(ABS(H13/I13-1)<='01_Assumptions'!$F$19,"Green",IF(ABS(H13/I13-1)<='01_Assumptions'!$E$19,"Amber","Red")))))
B14: ='01_Assumptions'!B20 | C14: =INDEX('02_Actuals'!C13:N13,1,'01_Assumptions'!$C$5) | D14: =INDEX('01_Assumptions'!C35:N35,1,'01_Assumptions'!$C$5) | E14: =C14-D14 | F14: =IF(D14=0,"—",C14/D14-1) | G14: =IF(D14=0,"—",IF('01_Assumptions'!$D$20="H",IF(C14>=D14,"Green",IF(C14>=D14*(1-'01_Assumptions'!$E$20),"Amber","Red")),IF('01_Assumptions'!$D$20="L",IF(C14<=D14,"Green",IF(C14<=D14*(1+'01_Assumptions'!$E$20),"Amber","Red")),IF(ABS(C14/D14-1)<='01_Assumptions'!$F$20,"Green",IF(ABS(C14/D14-1)<='01_Assumptions'!$E$20,"Amber","Red"))))) | H14: ='02_Actuals'!C28 | I14: ='02_Actuals'!D28 | J14: =H14-I14 | K14: =IF(I14=0,"—",IF('01_Assumptions'!$D$20="H",IF(H14>=I14,"Green",IF(H14>=I14*(1-'01_Assumptions'!$E$20),"Amber","Red")),IF('01_Assumptions'!$D$20="L",IF(H14<=I14,"Green",IF(H14<=I14*(1+'01_Assumptions'!$E$20),"Amber","Red")),IF(ABS(H14/I14-1)<='01_Assumptions'!$F$20,"Green",IF(ABS(H14/I14-1)<='01_Assumptions'!$E$20,"Amber","Red")))))
B15: ='01_Assumptions'!B21 | C15: =INDEX('02_Actuals'!C14:N14,1,'01_Assumptions'!$C$5) | D15: =INDEX('01_Assumptions'!C36:N36,1,'01_Assumptions'!$C$5) | E15: =C15-D15 | F15: =IF(D15=0,"—",C15/D15-1) | G15: =IF(D15=0,"—",IF('01_Assumptions'!$D$21="H",IF(C15>=D15,"Green",IF(C15>=D15*(1-'01_Assumptions'!$E$21),"Amber","Red")),IF('01_Assumptions'!$D$21="L",IF(C15<=D15,"Green",IF(C15<=D15*(1+'01_Assumptions'!$E$21),"Amber","Red")),IF(ABS(C15/D15-1)<='01_Assumptions'!$F$21,"Green",IF(ABS(C15/D15-1)<='01_Assumptions'!$E$21,"Amber","Red"))))) | H15: ='02_Actuals'!C29 | I15: ='02_Actuals'!D29 | J15: =H15-I15 | K15: =IF(I15=0,"—",IF('01_Assumptions'!$D$21="H",IF(H15>=I15,"Green",IF(H15>=I15*(1-'01_Assumptions'!$E$21),"Amber","Red")),IF('01_Assumptions'!$D$21="L",IF(H15<=I15,"Green",IF(H15<=I15*(1+'01_Assumptions'!$E$21),"Amber","Red")),IF(ABS(H15/I15-1)<='01_Assumptions'!$F$21,"Green",IF(ABS(H15/I15-1)<='01_Assumptions'!$E$21,"Amber","Red")))))
B16: ='01_Assumptions'!B22 | C16: =INDEX('02_Actuals'!C15:N15,1,'01_Assumptions'!$C$5) | D16: =INDEX('01_Assumptions'!C37:N37,1,'01_Assumptions'!$C$5) | E16: =C16-D16 | F16: =IF(D16=0,"—",C16/D16-1) | G16: =IF(D16=0,"—",IF('01_Assumptions'!$D$22="H",IF(C16>=D16,"Green",IF(C16>=D16*(1-'01_Assumptions'!$E$22),"Amber","Red")),IF('01_Assumptions'!$D$22="L",IF(C16<=D16,"Green",IF(C16<=D16*(1+'01_Assumptions'!$E$22),"Amber","Red")),IF(ABS(C16/D16-1)<='01_Assumptions'!$F$22,"Green",IF(ABS(C16/D16-1)<='01_Assumptions'!$E$22,"Amber","Red"))))) | H16: ='02_Actuals'!C30 | I16: ='02_Actuals'!D30 | J16: =H16-I16 | K16: =IF(I16=0,"—",IF('01_Assumptions'!$D$22="H",IF(H16>=I16,"Green",IF(H16>=I16*(1-'01_Assumptions'!$E$22),"Amber","Red")),IF('01_Assumptions'!$D$22="L",IF(H16<=I16,"Green",IF(H16<=I16*(1+'01_Assumptions'!$E$22),"Amber","Red")),IF(ABS(H16/I16-1)<='01_Assumptions'!$F$22,"Green",IF(ABS(H16/I16-1)<='01_Assumptions'!$E$22,"Amber","Red")))))
B17: ='01_Assumptions'!B23 | C17: =INDEX('02_Actuals'!C16:N16,1,'01_Assumptions'!$C$5) | D17: =INDEX('01_Assumptions'!C38:N38,1,'01_Assumptions'!$C$5) | E17: =C17-D17 | F17: =IF(D17=0,"—",C17/D17-1) | G17: =IF(D17=0,"—",IF('01_Assumptions'!$D$23="H",IF(C17>=D17,"Green",IF(C17>=D17*(1-'01_Assumptions'!$E$23),"Amber","Red")),IF('01_Assumptions'!$D$23="L",IF(C17<=D17,"Green",IF(C17<=D17*(1+'01_Assumptions'!$E$23),"Amber","Red")),IF(ABS(C17/D17-1)<='01_Assumptions'!$F$23,"Green",IF(ABS(C17/D17-1)<='01_Assumptions'!$E$23,"Amber","Red"))))) | H17: ='02_Actuals'!C31 | I17: ='02_Actuals'!D31 | J17: =H17-I17 | K17: =IF(I17=0,"—",IF('01_Assumptions'!$D$23="H",IF(H17>=I17,"Green",IF(H17>=I17*(1-'01_Assumptions'!$E$23),"Amber","Red")),IF('01_Assumptions'!$D$23="L",IF(H17<=I17,"Green",IF(H17<=I17*(1+'01_Assumptions'!$E$23),"Amber","Red")),IF(ABS(H17/I17-1)<='01_Assumptions'!$F$23,"Green",IF(ABS(H17/I17-1)<='01_Assumptions'!$E$23,"Amber","Red")))))
B18: ='01_Assumptions'!B24 | C18: =INDEX('02_Actuals'!C17:N17,1,'01_Assumptions'!$C$5) | D18: =INDEX('01_Assumptions'!C39:N39,1,'01_Assumptions'!$C$5) | E18: =C18-D18 | F18: =IF(D18=0,"—",C18/D18-1) | G18: =IF(D18=0,"—",IF('01_Assumptions'!$D$24="H",IF(C18>=D18,"Green",IF(C18>=D18*(1-'01_Assumptions'!$E$24),"Amber","Red")),IF('01_Assumptions'!$D$24="L",IF(C18<=D18,"Green",IF(C18<=D18*(1+'01_Assumptions'!$E$24),"Amber","Red")),IF(ABS(C18/D18-1)<='01_Assumptions'!$F$24,"Green",IF(ABS(C18/D18-1)<='01_Assumptions'!$E$24,"Amber","Red"))))) | H18: ='02_Actuals'!C32 | I18: ='02_Actuals'!D32 | J18: =H18-I18 | K18: =IF(I18=0,"—",IF('01_Assumptions'!$D$24="H",IF(H18>=I18,"Green",IF(H18>=I18*(1-'01_Assumptions'!$E$24),"Amber","Red")),IF('01_Assumptions'!$D$24="L",IF(H18<=I18,"Green",IF(H18<=I18*(1+'01_Assumptions'!$E$24),"Amber","Red")),IF(ABS(H18/I18-1)<='01_Assumptions'!$F$24,"Green",IF(ABS(H18/I18-1)<='01_Assumptions'!$E$24,"Amber","Red")))))
B19: ='01_Assumptions'!B25 | C19: =INDEX('02_Actuals'!C18:N18,1,'01_Assumptions'!$C$5) | D19: =INDEX('01_Assumptions'!C40:N40,1,'01_Assumptions'!$C$5) | E19: =C19-D19 | F19: =IF(D19=0,"—",C19/D19-1) | G19: =IF(D19=0,"—",IF('01_Assumptions'!$D$25="H",IF(C19>=D19,"Green",IF(C19>=D19*(1-'01_Assumptions'!$E$25),"Amber","Red")),IF('01_Assumptions'!$D$25="L",IF(C19<=D19,"Green",IF(C19<=D19*(1+'01_Assumptions'!$E$25),"Amber","Red")),IF(ABS(C19/D19-1)<='01_Assumptions'!$F$25,"Green",IF(ABS(C19/D19-1)<='01_Assumptions'!$E$25,"Amber","Red"))))) | H19: ='02_Actuals'!C33 | I19: ='02_Actuals'!D33 | J19: =H19-I19 | K19: =IF(I19=0,"—",IF('01_Assumptions'!$D$25="H",IF(H19>=I19,"Green",IF(H19>=I19*(1-'01_Assumptions'!$E$25),"Amber","Red")),IF('01_Assumptions'!$D$25="L",IF(H19<=I19,"Green",IF(H19<=I19*(1+'01_Assumptions'!$E$25),"Amber","Red")),IF(ABS(H19/I19-1)<='01_Assumptions'!$F$25,"Green",IF(ABS(H19/I19-1)<='01_Assumptions'!$E$25,"Amber","Red")))))
B21: Monthly RAG heatmap
C22: Jan-26 | D22: Feb-26 | E22: Mar-26 | F22: Apr-26 | G22: May-26 | H22: Jun-26 | I22: Jul-26 | J22: Aug-26 | K22: Sep-26 | L22: Oct-26 | M22: Nov-26 | N22: Dec-26
B23: Net revenue | C23: =IF('01_Assumptions'!C29=0,"—",IF('01_Assumptions'!$D$14="H",IF('02_Actuals'!C7>='01_Assumptions'!C29,"Green",IF('02_Actuals'!C7>='01_Assumptions'!C29*(1-'01_Assumptions'!$E$14),"Amber","Red")),IF('01_Assumptions'!$D$14="L",IF('02_Actuals'!C7<='01_Assumptions'!C29,"Green",IF('02_Actuals'!C7<='01_Assumptions'!C29*(1+'01_Assumptions'!$E$14),"Amber","Red")),IF(ABS('02_Actuals'!C7/'01_Assumptions'!C29-1)<='01_Assumptions'!$F$14,"Green",IF(ABS('02_Actuals'!C7/'01_Assumptions'!C29-1)<='01_Assumptions'!$E$14,"Amber","Red"))))) | D23: =IF('01_Assumptions'!D29=0,"—",IF('01_Assumptions'!$D$14="H",IF('02_Actuals'!D7>='01_Assumptions'!D29,"Green",IF('02_Actuals'!D7>='01_Assumptions'!D29*(1-'01_Assumptions'!$E$14),"Amber","Red")),IF('01_Assumptions'!$D$14="L",IF('02_Actuals'!D7<='01_Assumptions'!D29,"Green",IF('02_Actuals'!D7<='01_Assumptions'!D29*(1+'01_Assumptions'!$E$14),"Amber","Red")),IF(ABS('02_Actuals'!D7/'01_Assumptions'!D29-1)<='01_Assumptions'!$F$14,"Green",IF(ABS('02_Actuals'!D7/'01_Assumptions'!D29-1)<='01_Assumptions'!$E$14,"Amber","Red"))))) | E23: =IF('01_Assumptions'!E29=0,"—",IF('01_Assumptions'!$D$14="H",IF('02_Actuals'!E7>='01_Assumptions'!E29,"Green",IF('02_Actuals'!E7>='01_Assumptions'!E29*(1-'01_Assumptions'!$E$14),"Amber","Red")),IF('01_Assumptions'!$D$14="L",IF('02_Actuals'!E7<='01_Assumptions'!E29,"Green",IF('02_Actuals'!E7<='01_Assumptions'!E29*(1+'01_Assumptions'!$E$14),"Amber","Red")),IF(ABS('02_Actuals'!E7/'01_Assumptions'!E29-1)<='01_Assumptions'!$F$14,"Green",IF(ABS('02_Actuals'!E7/'01_Assumptions'!E29-1)<='01_Assumptions'!$E$14,"Amber","Red"))))) | F23: =IF('01_Assumptions'!F29=0,"—",IF('01_Assumptions'!$D$14="H",IF('02_Actuals'!F7>='01_Assumptions'!F29,"Green",IF('02_Actuals'!F7>='01_Assumptions'!F29*(1-'01_Assumptions'!$E$14),"Amber","Red")),IF('01_Assumptions'!$D$14="L",IF('02_Actuals'!F7<='01_Assumptions'!F29,"Green",IF('02_Actuals'!F7<='01_Assumptions'!F29*(1+'01_Assumptions'!$E$14),"Amber","Red")),IF(ABS('02_Actuals'!F7/'01_Assumptions'!F29-1)<='01_Assumptions'!$F$14,"Green",IF(ABS('02_Actuals'!F7/'01_Assumptions'!F29-1)<='01_Assumptions'!$E$14,"Amber","Red"))))) | G23: =IF('01_Assumptions'!G29=0,"—",IF('01_Assumptions'!$D$14="H",IF('02_Actuals'!G7>='01_Assumptions'!G29,"Green",IF('02_Actuals'!G7>='01_Assumptions'!G29*(1-'01_Assumptions'!$E$14),"Amber","Red")),IF('01_Assumptions'!$D$14="L",IF('02_Actuals'!G7<='01_Assumptions'!G29,"Green",IF('02_Actuals'!G7<='01_Assumptions'!G29*(1+'01_Assumptions'!$E$14),"Amber","Red")),IF(ABS('02_Actuals'!G7/'01_Assumptions'!G29-1)<='01_Assumptions'!$F$14,"Green",IF(ABS('02_Actuals'!G7/'01_Assumptions'!G29-1)<='01_Assumptions'!$E$14,"Amber","Red"))))) | H23: =IF('01_Assumptions'!H29=0,"—",IF('01_Assumptions'!$D$14="H",IF('02_Actuals'!H7>='01_Assumptions'!H29,"Green",IF('02_Actuals'!H7>='01_Assumptions'!H29*(1-'01_Assumptions'!$E$14),"Amber","Red")),IF('01_Assumptions'!$D$14="L",IF('02_Actuals'!H7<='01_Assumptions'!H29,"Green",IF('02_Actuals'!H7<='01_Assumptions'!H29*(1+'01_Assumptions'!$E$14),"Amber","Red")),IF(ABS('02_Actuals'!H7/'01_Assumptions'!H29-1)<='01_Assumptions'!$F$14,"Green",IF(ABS('02_Actuals'!H7/'01_Assumptions'!H29-1)<='01_Assumptions'!$E$14,"Amber","Red"))))) | I23: =IF('01_Assumptions'!I29=0,"—",IF('01_Assumptions'!$D$14="H",IF('02_Actuals'!I7>='01_Assumptions'!I29,"Green",IF('02_Actuals'!I7>='01_Assumptions'!I29*(1-'01_Assumptions'!$E$14),"Amber","Red")),IF('01_Assumptions'!$D$14="L",IF('02_Actuals'!I7<='01_Assumptions'!I29,"Green",IF('02_Actuals'!I7<='01_Assumptions'!I29*(1+'01_Assumptions'!$E$14),"Amber","Red")),IF(ABS('02_Actuals'!I7/'01_Assumptions'!I29-1)<='01_Assumptions'!$F$14,"Green",IF(ABS('02_Actuals'!I7/'01_Assumptions'!I29-1)<='01_Assumptions'!$E$14,"Amber","Red"))))) | J23: =IF('01_Assumptions'!J29=0,"—",IF('01_Assumptions'!$D$14="H",IF('02_Actuals'!J7>='01_Assumptions'!J29,"Green",IF('02_Actuals'!J7>='01_Assumptions'!J29*(1-'01_Assumptions'!$E$14),"Amber","Red")),IF('01_Assumptions'!$D$14="L",IF('02_Actuals'!J7<='01_Assumptions'!J29,"Green",IF('02_Actuals'!J7<='01_Assumptions'!J29*(1+'01_Assumptions'!$E$14),"Amber","Red")),IF(ABS('02_Actuals'!J7/'01_Assumptions'!J29-1)<='01_Assumptions'!$F$14,"Green",IF(ABS('02_Actuals'!J7/'01_Assumptions'!J29-1)<='01_Assumptions'!$E$14,"Amber","Red"))))) | ... N23: =IF('01_Assumptions'!N29=0,"—",IF('01_Assumptions'!$D$14="H",IF('02_Actuals'!N7>='01_Assumptions'!N29,"Green",IF('02_Actuals'!N7>='01_Assumptions'!N29*(1-'01_Assumptions'!$E$14),"Amber","Red")),IF('01_Assumptions'!$D$14="L",IF('02_Actuals'!N7<='01_Assumptions'!N29,"Green",IF('02_Actuals'!N7<='01_Assumptions'!N29*(1+'01_Assumptions'!$E$14),"Amber","Red")),IF(ABS('02_Actuals'!N7/'01_Assumptions'!N29-1)<='01_Assumptions'!$F$14,"Green",IF(ABS('02_Actuals'!N7/'01_Assumptions'!N29-1)<='01_Assumptions'!$E$14,"Amber","Red")))))
B24: Gross margin % | C24: =IF('01_Assumptions'!C30=0,"—",IF('01_Assumptions'!$D$15="H",IF('02_Actuals'!C8>='01_Assumptions'!C30,"Green",IF('02_Actuals'!C8>='01_Assumptions'!C30*(1-'01_Assumptions'!$E$15),"Amber","Red")),IF('01_Assumptions'!$D$15="L",IF('02_Actuals'!C8<='01_Assumptions'!C30,"Green",IF('02_Actuals'!C8<='01_Assumptions'!C30*(1+'01_Assumptions'!$E$15),"Amber","Red")),IF(ABS('02_Actuals'!C8/'01_Assumptions'!C30-1)<='01_Assumptions'!$F$15,"Green",IF(ABS('02_Actuals'!C8/'01_Assumptions'!C30-1)<='01_Assumptions'!$E$15,"Amber","Red"))))) | D24: =IF('01_Assumptions'!D30=0,"—",IF('01_Assumptions'!$D$15="H",IF('02_Actuals'!D8>='01_Assumptions'!D30,"Green",IF('02_Actuals'!D8>='01_Assumptions'!D30*(1-'01_Assumptions'!$E$15),"Amber","Red")),IF('01_Assumptions'!$D$15="L",IF('02_Actuals'!D8<='01_Assumptions'!D30,"Green",IF('02_Actuals'!D8<='01_Assumptions'!D30*(1+'01_Assumptions'!$E$15),"Amber","Red")),IF(ABS('02_Actuals'!D8/'01_Assumptions'!D30-1)<='01_Assumptions'!$F$15,"Green",IF(ABS('02_Actuals'!D8/'01_Assumptions'!D30-1)<='01_Assumptions'!$E$15,"Amber","Red"))))) | E24: =IF('01_Assumptions'!E30=0,"—",IF('01_Assumptions'!$D$15="H",IF('02_Actuals'!E8>='01_Assumptions'!E30,"Green",IF('02_Actuals'!E8>='01_Assumptions'!E30*(1-'01_Assumptions'!$E$15),"Amber","Red")),IF('01_Assumptions'!$D$15="L",IF('02_Actuals'!E8<='01_Assumptions'!E30,"Green",IF('02_Actuals'!E8<='01_Assumptions'!E30*(1+'01_Assumptions'!$E$15),"Amber","Red")),IF(ABS('02_Actuals'!E8/'01_Assumptions'!E30-1)<='01_Assumptions'!$F$15,"Green",IF(ABS('02_Actuals'!E8/'01_Assumptions'!E30-1)<='01_Assumptions'!$E$15,"Amber","Red"))))) | F24: =IF('01_Assumptions'!F30=0,"—",IF('01_Assumptions'!$D$15="H",IF('02_Actuals'!F8>='01_Assumptions'!F30,"Green",IF('02_Actuals'!F8>='01_Assumptions'!F30*(1-'01_Assumptions'!$E$15),"Amber","Red")),IF('01_Assumptions'!$D$15="L",IF('02_Actuals'!F8<='01_Assumptions'!F30,"Green",IF('02_Actuals'!F8<='01_Assumptions'!F30*(1+'01_Assumptions'!$E$15),"Amber","Red")),IF(ABS('02_Actuals'!F8/'01_Assumptions'!F30-1)<='01_Assumptions'!$F$15,"Green",IF(ABS('02_Actuals'!F8/'01_Assumptions'!F30-1)<='01_Assumptions'!$E$15,"Amber","Red"))))) | G24: =IF('01_Assumptions'!G30=0,"—",IF('01_Assumptions'!$D$15="H",IF('02_Actuals'!G8>='01_Assumptions'!G30,"Green",IF('02_Actuals'!G8>='01_Assumptions'!G30*(1-'01_Assumptions'!$E$15),"Amber","Red")),IF('01_Assumptions'!$D$15="L",IF('02_Actuals'!G8<='01_Assumptions'!G30,"Green",IF('02_Actuals'!G8<='01_Assumptions'!G30*(1+'01_Assumptions'!$E$15),"Amber","Red")),IF(ABS('02_Actuals'!G8/'01_Assumptions'!G30-1)<='01_Assumptions'!$F$15,"Green",IF(ABS('02_Actuals'!G8/'01_Assumptions'!G30-1)<='01_Assumptions'!$E$15,"Amber","Red"))))) | H24: =IF('01_Assumptions'!H30=0,"—",IF('01_Assumptions'!$D$15="H",IF('02_Actuals'!H8>='01_Assumptions'!H30,"Green",IF('02_Actuals'!H8>='01_Assumptions'!H30*(1-'01_Assumptions'!$E$15),"Amber","Red")),IF('01_Assumptions'!$D$15="L",IF('02_Actuals'!H8<='01_Assumptions'!H30,"Green",IF('02_Actuals'!H8<='01_Assumptions'!H30*(1+'01_Assumptions'!$E$15),"Amber","Red")),IF(ABS('02_Actuals'!H8/'01_Assumptions'!H30-1)<='01_Assumptions'!$F$15,"Green",IF(ABS('02_Actuals'!H8/'01_Assumptions'!H30-1)<='01_Assumptions'!$E$15,"Amber","Red"))))) | I24: =IF('01_Assumptions'!I30=0,"—",IF('01_Assumptions'!$D$15="H",IF('02_Actuals'!I8>='01_Assumptions'!I30,"Green",IF('02_Actuals'!I8>='01_Assumptions'!I30*(1-'01_Assumptions'!$E$15),"Amber","Red")),IF('01_Assumptions'!$D$15="L",IF('02_Actuals'!I8<='01_Assumptions'!I30,"Green",IF('02_Actuals'!I8<='01_Assumptions'!I30*(1+'01_Assumptions'!$E$15),"Amber","Red")),IF(ABS('02_Actuals'!I8/'01_Assumptions'!I30-1)<='01_Assumptions'!$F$15,"Green",IF(ABS('02_Actuals'!I8/'01_Assumptions'!I30-1)<='01_Assumptions'!$E$15,"Amber","Red"))))) | J24: =IF('01_Assumptions'!J30=0,"—",IF('01_Assumptions'!$D$15="H",IF('02_Actuals'!J8>='01_Assumptions'!J30,"Green",IF('02_Actuals'!J8>='01_Assumptions'!J30*(1-'01_Assumptions'!$E$15),"Amber","Red")),IF('01_Assumptions'!$D$15="L",IF('02_Actuals'!J8<='01_Assumptions'!J30,"Green",IF('02_Actuals'!J8<='01_Assumptions'!J30*(1+'01_Assumptions'!$E$15),"Amber","Red")),IF(ABS('02_Actuals'!J8/'01_Assumptions'!J30-1)<='01_Assumptions'!$F$15,"Green",IF(ABS('02_Actuals'!J8/'01_Assumptions'!J30-1)<='01_Assumptions'!$E$15,"Amber","Red"))))) | ... N24: =IF('01_Assumptions'!N30=0,"—",IF('01_Assumptions'!$D$15="H",IF('02_Actuals'!N8>='01_Assumptions'!N30,"Green",IF('02_Actuals'!N8>='01_Assumptions'!N30*(1-'01_Assumptions'!$E$15),"Amber","Red")),IF('01_Assumptions'!$D$15="L",IF('02_Actuals'!N8<='01_Assumptions'!N30,"Green",IF('02_Actuals'!N8<='01_Assumptions'!N30*(1+'01_Assumptions'!$E$15),"Amber","Red")),IF(ABS('02_Actuals'!N8/'01_Assumptions'!N30-1)<='01_Assumptions'!$F$15,"Green",IF(ABS('02_Actuals'!N8/'01_Assumptions'!N30-1)<='01_Assumptions'!$E$15,"Amber","Red")))))
B25: EBITDA | C25: =IF('01_Assumptions'!C31=0,"—",IF('01_Assumptions'!$D$16="H",IF('02_Actuals'!C9>='01_Assumptions'!C31,"Green",IF('02_Actuals'!C9>='01_Assumptions'!C31*(1-'01_Assumptions'!$E$16),"Amber","Red")),IF('01_Assumptions'!$D$16="L",IF('02_Actuals'!C9<='01_Assumptions'!C31,"Green",IF('02_Actuals'!C9<='01_Assumptions'!C31*(1+'01_Assumptions'!$E$16),"Amber","Red")),IF(ABS('02_Actuals'!C9/'01_Assumptions'!C31-1)<='01_Assumptions'!$F$16,"Green",IF(ABS('02_Actuals'!C9/'01_Assumptions'!C31-1)<='01_Assumptions'!$E$16,"Amber","Red"))))) | D25: =IF('01_Assumptions'!D31=0,"—",IF('01_Assumptions'!$D$16="H",IF('02_Actuals'!D9>='01_Assumptions'!D31,"Green",IF('02_Actuals'!D9>='01_Assumptions'!D31*(1-'01_Assumptions'!$E$16),"Amber","Red")),IF('01_Assumptions'!$D$16="L",IF('02_Actuals'!D9<='01_Assumptions'!D31,"Green",IF('02_Actuals'!D9<='01_Assumptions'!D31*(1+'01_Assumptions'!$E$16),"Amber","Red")),IF(ABS('02_Actuals'!D9/'01_Assumptions'!D31-1)<='01_Assumptions'!$F$16,"Green",IF(ABS('02_Actuals'!D9/'01_Assumptions'!D31-1)<='01_Assumptions'!$E$16,"Amber","Red"))))) | E25: =IF('01_Assumptions'!E31=0,"—",IF('01_Assumptions'!$D$16="H",IF('02_Actuals'!E9>='01_Assumptions'!E31,"Green",IF('02_Actuals'!E9>='01_Assumptions'!E31*(1-'01_Assumptions'!$E$16),"Amber","Red")),IF('01_Assumptions'!$D$16="L",IF('02_Actuals'!E9<='01_Assumptions'!E31,"Green",IF('02_Actuals'!E9<='01_Assumptions'!E31*(1+'01_Assumptions'!$E$16),"Amber","Red")),IF(ABS('02_Actuals'!E9/'01_Assumptions'!E31-1)<='01_Assumptions'!$F$16,"Green",IF(ABS('02_Actuals'!E9/'01_Assumptions'!E31-1)<='01_Assumptions'!$E$16,"Amber","Red"))))) | F25: =IF('01_Assumptions'!F31=0,"—",IF('01_Assumptions'!$D$16="H",IF('02_Actuals'!F9>='01_Assumptions'!F31,"Green",IF('02_Actuals'!F9>='01_Assumptions'!F31*(1-'01_Assumptions'!$E$16),"Amber","Red")),IF('01_Assumptions'!$D$16="L",IF('02_Actuals'!F9<='01_Assumptions'!F31,"Green",IF('02_Actuals'!F9<='01_Assumptions'!F31*(1+'01_Assumptions'!$E$16),"Amber","Red")),IF(ABS('02_Actuals'!F9/'01_Assumptions'!F31-1)<='01_Assumptions'!$F$16,"Green",IF(ABS('02_Actuals'!F9/'01_Assumptions'!F31-1)<='01_Assumptions'!$E$16,"Amber","Red"))))) | G25: =IF('01_Assumptions'!G31=0,"—",IF('01_Assumptions'!$D$16="H",IF('02_Actuals'!G9>='01_Assumptions'!G31,"Green",IF('02_Actuals'!G9>='01_Assumptions'!G31*(1-'01_Assumptions'!$E$16),"Amber","Red")),IF('01_Assumptions'!$D$16="L",IF('02_Actuals'!G9<='01_Assumptions'!G31,"Green",IF('02_Actuals'!G9<='01_Assumptions'!G31*(1+'01_Assumptions'!$E$16),"Amber","Red")),IF(ABS('02_Actuals'!G9/'01_Assumptions'!G31-1)<='01_Assumptions'!$F$16,"Green",IF(ABS('02_Actuals'!G9/'01_Assumptions'!G31-1)<='01_Assumptions'!$E$16,"Amber","Red"))))) | H25: =IF('01_Assumptions'!H31=0,"—",IF('01_Assumptions'!$D$16="H",IF('02_Actuals'!H9>='01_Assumptions'!H31,"Green",IF('02_Actuals'!H9>='01_Assumptions'!H31*(1-'01_Assumptions'!$E$16),"Amber","Red")),IF('01_Assumptions'!$D$16="L",IF('02_Actuals'!H9<='01_Assumptions'!H31,"Green",IF('02_Actuals'!H9<='01_Assumptions'!H31*(1+'01_Assumptions'!$E$16),"Amber","Red")),IF(ABS('02_Actuals'!H9/'01_Assumptions'!H31-1)<='01_Assumptions'!$F$16,"Green",IF(ABS('02_Actuals'!H9/'01_Assumptions'!H31-1)<='01_Assumptions'!$E$16,"Amber","Red"))))) | I25: =IF('01_Assumptions'!I31=0,"—",IF('01_Assumptions'!$D$16="H",IF('02_Actuals'!I9>='01_Assumptions'!I31,"Green",IF('02_Actuals'!I9>='01_Assumptions'!I31*(1-'01_Assumptions'!$E$16),"Amber","Red")),IF('01_Assumptions'!$D$16="L",IF('02_Actuals'!I9<='01_Assumptions'!I31,"Green",IF('02_Actuals'!I9<='01_Assumptions'!I31*(1+'01_Assumptions'!$E$16),"Amber","Red")),IF(ABS('02_Actuals'!I9/'01_Assumptions'!I31-1)<='01_Assumptions'!$F$16,"Green",IF(ABS('02_Actuals'!I9/'01_Assumptions'!I31-1)<='01_Assumptions'!$E$16,"Amber","Red"))))) | J25: =IF('01_Assumptions'!J31=0,"—",IF('01_Assumptions'!$D$16="H",IF('02_Actuals'!J9>='01_Assumptions'!J31,"Green",IF('02_Actuals'!J9>='01_Assumptions'!J31*(1-'01_Assumptions'!$E$16),"Amber","Red")),IF('01_Assumptions'!$D$16="L",IF('02_Actuals'!J9<='01_Assumptions'!J31,"Green",IF('02_Actuals'!J9<='01_Assumptions'!J31*(1+'01_Assumptions'!$E$16),"Amber","Red")),IF(ABS('02_Actuals'!J9/'01_Assumptions'!J31-1)<='01_Assumptions'!$F$16,"Green",IF(ABS('02_Actuals'!J9/'01_Assumptions'!J31-1)<='01_Assumptions'!$E$16,"Amber","Red"))))) | ... N25: =IF('01_Assumptions'!N31=0,"—",IF('01_Assumptions'!$D$16="H",IF('02_Actuals'!N9>='01_Assumptions'!N31,"Green",IF('02_Actuals'!N9>='01_Assumptions'!N31*(1-'01_Assumptions'!$E$16),"Amber","Red")),IF('01_Assumptions'!$D$16="L",IF('02_Actuals'!N9<='01_Assumptions'!N31,"Green",IF('02_Actuals'!N9<='01_Assumptions'!N31*(1+'01_Assumptions'!$E$16),"Amber","Red")),IF(ABS('02_Actuals'!N9/'01_Assumptions'!N31-1)<='01_Assumptions'!$F$16,"Green",IF(ABS('02_Actuals'!N9/'01_Assumptions'!N31-1)<='01_Assumptions'!$E$16,"Amber","Red")))))
B26: Volume | C26: =IF('01_Assumptions'!C32=0,"—",IF('01_Assumptions'!$D$17="H",IF('02_Actuals'!C10>='01_Assumptions'!C32,"Green",IF('02_Actuals'!C10>='01_Assumptions'!C32*(1-'01_Assumptions'!$E$17),"Amber","Red")),IF('01_Assumptions'!$D$17="L",IF('02_Actuals'!C10<='01_Assumptions'!C32,"Green",IF('02_Actuals'!C10<='01_Assumptions'!C32*(1+'01_Assumptions'!$E$17),"Amber","Red")),IF(ABS('02_Actuals'!C10/'01_Assumptions'!C32-1)<='01_Assumptions'!$F$17,"Green",IF(ABS('02_Actuals'!C10/'01_Assumptions'!C32-1)<='01_Assumptions'!$E$17,"Amber","Red"))))) | D26: =IF('01_Assumptions'!D32=0,"—",IF('01_Assumptions'!$D$17="H",IF('02_Actuals'!D10>='01_Assumptions'!D32,"Green",IF('02_Actuals'!D10>='01_Assumptions'!D32*(1-'01_Assumptions'!$E$17),"Amber","Red")),IF('01_Assumptions'!$D$17="L",IF('02_Actuals'!D10<='01_Assumptions'!D32,"Green",IF('02_Actuals'!D10<='01_Assumptions'!D32*(1+'01_Assumptions'!$E$17),"Amber","Red")),IF(ABS('02_Actuals'!D10/'01_Assumptions'!D32-1)<='01_Assumptions'!$F$17,"Green",IF(ABS('02_Actuals'!D10/'01_Assumptions'!D32-1)<='01_Assumptions'!$E$17,"Amber","Red"))))) | E26: =IF('01_Assumptions'!E32=0,"—",IF('01_Assumptions'!$D$17="H",IF('02_Actuals'!E10>='01_Assumptions'!E32,"Green",IF('02_Actuals'!E10>='01_Assumptions'!E32*(1-'01_Assumptions'!$E$17),"Amber","Red")),IF('01_Assumptions'!$D$17="L",IF('02_Actuals'!E10<='01_Assumptions'!E32,"Green",IF('02_Actuals'!E10<='01_Assumptions'!E32*(1+'01_Assumptions'!$E$17),"Amber","Red")),IF(ABS('02_Actuals'!E10/'01_Assumptions'!E32-1)<='01_Assumptions'!$F$17,"Green",IF(ABS('02_Actuals'!E10/'01_Assumptions'!E32-1)<='01_Assumptions'!$E$17,"Amber","Red"))))) | F26: =IF('01_Assumptions'!F32=0,"—",IF('01_Assumptions'!$D$17="H",IF('02_Actuals'!F10>='01_Assumptions'!F32,"Green",IF('02_Actuals'!F10>='01_Assumptions'!F32*(1-'01_Assumptions'!$E$17),"Amber","Red")),IF('01_Assumptions'!$D$17="L",IF('02_Actuals'!F10<='01_Assumptions'!F32,"Green",IF('02_Actuals'!F10<='01_Assumptions'!F32*(1+'01_Assumptions'!$E$17),"Amber","Red")),IF(ABS('02_Actuals'!F10/'01_Assumptions'!F32-1)<='01_Assumptions'!$F$17,"Green",IF(ABS('02_Actuals'!F10/'01_Assumptions'!F32-1)<='01_Assumptions'!$E$17,"Amber","Red"))))) | G26: =IF('01_Assumptions'!G32=0,"—",IF('01_Assumptions'!$D$17="H",IF('02_Actuals'!G10>='01_Assumptions'!G32,"Green",IF('02_Actuals'!G10>='01_Assumptions'!G32*(1-'01_Assumptions'!$E$17),"Amber","Red")),IF('01_Assumptions'!$D$17="L",IF('02_Actuals'!G10<='01_Assumptions'!G32,"Green",IF('02_Actuals'!G10<='01_Assumptions'!G32*(1+'01_Assumptions'!$E$17),"Amber","Red")),IF(ABS('02_Actuals'!G10/'01_Assumptions'!G32-1)<='01_Assumptions'!$F$17,"Green",IF(ABS('02_Actuals'!G10/'01_Assumptions'!G32-1)<='01_Assumptions'!$E$17,"Amber","Red"))))) | H26: =IF('01_Assumptions'!H32=0,"—",IF('01_Assumptions'!$D$17="H",IF('02_Actuals'!H10>='01_Assumptions'!H32,"Green",IF('02_Actuals'!H10>='01_Assumptions'!H32*(1-'01_Assumptions'!$E$17),"Amber","Red")),IF('01_Assumptions'!$D$17="L",IF('02_Actuals'!H10<='01_Assumptions'!H32,"Green",IF('02_Actuals'!H10<='01_Assumptions'!H32*(1+'01_Assumptions'!$E$17),"Amber","Red")),IF(ABS('02_Actuals'!H10/'01_Assumptions'!H32-1)<='01_Assumptions'!$F$17,"Green",IF(ABS('02_Actuals'!H10/'01_Assumptions'!H32-1)<='01_Assumptions'!$E$17,"Amber","Red"))))) | I26: =IF('01_Assumptions'!I32=0,"—",IF('01_Assumptions'!$D$17="H",IF('02_Actuals'!I10>='01_Assumptions'!I32,"Green",IF('02_Actuals'!I10>='01_Assumptions'!I32*(1-'01_Assumptions'!$E$17),"Amber","Red")),IF('01_Assumptions'!$D$17="L",IF('02_Actuals'!I10<='01_Assumptions'!I32,"Green",IF('02_Actuals'!I10<='01_Assumptions'!I32*(1+'01_Assumptions'!$E$17),"Amber","Red")),IF(ABS('02_Actuals'!I10/'01_Assumptions'!I32-1)<='01_Assumptions'!$F$17,"Green",IF(ABS('02_Actuals'!I10/'01_Assumptions'!I32-1)<='01_Assumptions'!$E$17,"Amber","Red"))))) | J26: =IF('01_Assumptions'!J32=0,"—",IF('01_Assumptions'!$D$17="H",IF('02_Actuals'!J10>='01_Assumptions'!J32,"Green",IF('02_Actuals'!J10>='01_Assumptions'!J32*(1-'01_Assumptions'!$E$17),"Amber","Red")),IF('01_Assumptions'!$D$17="L",IF('02_Actuals'!J10<='01_Assumptions'!J32,"Green",IF('02_Actuals'!J10<='01_Assumptions'!J32*(1+'01_Assumptions'!$E$17),"Amber","Red")),IF(ABS('02_Actuals'!J10/'01_Assumptions'!J32-1)<='01_Assumptions'!$F$17,"Green",IF(ABS('02_Actuals'!J10/'01_Assumptions'!J32-1)<='01_Assumptions'!$E$17,"Amber","Red"))))) | ... N26: =IF('01_Assumptions'!N32=0,"—",IF('01_Assumptions'!$D$17="H",IF('02_Actuals'!N10>='01_Assumptions'!N32,"Green",IF('02_Actuals'!N10>='01_Assumptions'!N32*(1-'01_Assumptions'!$E$17),"Amber","Red")),IF('01_Assumptions'!$D$17="L",IF('02_Actuals'!N10<='01_Assumptions'!N32,"Green",IF('02_Actuals'!N10<='01_Assumptions'!N32*(1+'01_Assumptions'!$E$17),"Amber","Red")),IF(ABS('02_Actuals'!N10/'01_Assumptions'!N32-1)<='01_Assumptions'!$F$17,"Green",IF(ABS('02_Actuals'!N10/'01_Assumptions'!N32-1)<='01_Assumptions'!$E$17,"Amber","Red")))))
B27: OTIF % | C27: =IF('01_Assumptions'!C33=0,"—",IF('01_Assumptions'!$D$18="H",IF('02_Actuals'!C11>='01_Assumptions'!C33,"Green",IF('02_Actuals'!C11>='01_Assumptions'!C33*(1-'01_Assumptions'!$E$18),"Amber","Red")),IF('01_Assumptions'!$D$18="L",IF('02_Actuals'!C11<='01_Assumptions'!C33,"Green",IF('02_Actuals'!C11<='01_Assumptions'!C33*(1+'01_Assumptions'!$E$18),"Amber","Red")),IF(ABS('02_Actuals'!C11/'01_Assumptions'!C33-1)<='01_Assumptions'!$F$18,"Green",IF(ABS('02_Actuals'!C11/'01_Assumptions'!C33-1)<='01_Assumptions'!$E$18,"Amber","Red"))))) | D27: =IF('01_Assumptions'!D33=0,"—",IF('01_Assumptions'!$D$18="H",IF('02_Actuals'!D11>='01_Assumptions'!D33,"Green",IF('02_Actuals'!D11>='01_Assumptions'!D33*(1-'01_Assumptions'!$E$18),"Amber","Red")),IF('01_Assumptions'!$D$18="L",IF('02_Actuals'!D11<='01_Assumptions'!D33,"Green",IF('02_Actuals'!D11<='01_Assumptions'!D33*(1+'01_Assumptions'!$E$18),"Amber","Red")),IF(ABS('02_Actuals'!D11/'01_Assumptions'!D33-1)<='01_Assumptions'!$F$18,"Green",IF(ABS('02_Actuals'!D11/'01_Assumptions'!D33-1)<='01_Assumptions'!$E$18,"Amber","Red"))))) | E27: =IF('01_Assumptions'!E33=0,"—",IF('01_Assumptions'!$D$18="H",IF('02_Actuals'!E11>='01_Assumptions'!E33,"Green",IF('02_Actuals'!E11>='01_Assumptions'!E33*(1-'01_Assumptions'!$E$18),"Amber","Red")),IF('01_Assumptions'!$D$18="L",IF('02_Actuals'!E11<='01_Assumptions'!E33,"Green",IF('02_Actuals'!E11<='01_Assumptions'!E33*(1+'01_Assumptions'!$E$18),"Amber","Red")),IF(ABS('02_Actuals'!E11/'01_Assumptions'!E33-1)<='01_Assumptions'!$F$18,"Green",IF(ABS('02_Actuals'!E11/'01_Assumptions'!E33-1)<='01_Assumptions'!$E$18,"Amber","Red"))))) | F27: =IF('01_Assumptions'!F33=0,"—",IF('01_Assumptions'!$D$18="H",IF('02_Actuals'!F11>='01_Assumptions'!F33,"Green",IF('02_Actuals'!F11>='01_Assumptions'!F33*(1-'01_Assumptions'!$E$18),"Amber","Red")),IF('01_Assumptions'!$D$18="L",IF('02_Actuals'!F11<='01_Assumptions'!F33,"Green",IF('02_Actuals'!F11<='01_Assumptions'!F33*(1+'01_Assumptions'!$E$18),"Amber","Red")),IF(ABS('02_Actuals'!F11/'01_Assumptions'!F33-1)<='01_Assumptions'!$F$18,"Green",IF(ABS('02_Actuals'!F11/'01_Assumptions'!F33-1)<='01_Assumptions'!$E$18,"Amber","Red"))))) | G27: =IF('01_Assumptions'!G33=0,"—",IF('01_Assumptions'!$D$18="H",IF('02_Actuals'!G11>='01_Assumptions'!G33,"Green",IF('02_Actuals'!G11>='01_Assumptions'!G33*(1-'01_Assumptions'!$E$18),"Amber","Red")),IF('01_Assumptions'!$D$18="L",IF('02_Actuals'!G11<='01_Assumptions'!G33,"Green",IF('02_Actuals'!G11<='01_Assumptions'!G33*(1+'01_Assumptions'!$E$18),"Amber","Red")),IF(ABS('02_Actuals'!G11/'01_Assumptions'!G33-1)<='01_Assumptions'!$F$18,"Green",IF(ABS('02_Actuals'!G11/'01_Assumptions'!G33-1)<='01_Assumptions'!$E$18,"Amber","Red"))))) | H27: =IF('01_Assumptions'!H33=0,"—",IF('01_Assumptions'!$D$18="H",IF('02_Actuals'!H11>='01_Assumptions'!H33,"Green",IF('02_Actuals'!H11>='01_Assumptions'!H33*(1-'01_Assumptions'!$E$18),"Amber","Red")),IF('01_Assumptions'!$D$18="L",IF('02_Actuals'!H11<='01_Assumptions'!H33,"Green",IF('02_Actuals'!H11<='01_Assumptions'!H33*(1+'01_Assumptions'!$E$18),"Amber","Red")),IF(ABS('02_Actuals'!H11/'01_Assumptions'!H33-1)<='01_Assumptions'!$F$18,"Green",IF(ABS('02_Actuals'!H11/'01_Assumptions'!H33-1)<='01_Assumptions'!$E$18,"Amber","Red"))))) | I27: =IF('01_Assumptions'!I33=0,"—",IF('01_Assumptions'!$D$18="H",IF('02_Actuals'!I11>='01_Assumptions'!I33,"Green",IF('02_Actuals'!I11>='01_Assumptions'!I33*(1-'01_Assumptions'!$E$18),"Amber","Red")),IF('01_Assumptions'!$D$18="L",IF('02_Actuals'!I11<='01_Assumptions'!I33,"Green",IF('02_Actuals'!I11<='01_Assumptions'!I33*(1+'01_Assumptions'!$E$18),"Amber","Red")),IF(ABS('02_Actuals'!I11/'01_Assumptions'!I33-1)<='01_Assumptions'!$F$18,"Green",IF(ABS('02_Actuals'!I11/'01_Assumptions'!I33-1)<='01_Assumptions'!$E$18,"Amber","Red"))))) | J27: =IF('01_Assumptions'!J33=0,"—",IF('01_Assumptions'!$D$18="H",IF('02_Actuals'!J11>='01_Assumptions'!J33,"Green",IF('02_Actuals'!J11>='01_Assumptions'!J33*(1-'01_Assumptions'!$E$18),"Amber","Red")),IF('01_Assumptions'!$D$18="L",IF('02_Actuals'!J11<='01_Assumptions'!J33,"Green",IF('02_Actuals'!J11<='01_Assumptions'!J33*(1+'01_Assumptions'!$E$18),"Amber","Red")),IF(ABS('02_Actuals'!J11/'01_Assumptions'!J33-1)<='01_Assumptions'!$F$18,"Green",IF(ABS('02_Actuals'!J11/'01_Assumptions'!J33-1)<='01_Assumptions'!$E$18,"Amber","Red"))))) | ... N27: =IF('01_Assumptions'!N33=0,"—",IF('01_Assumptions'!$D$18="H",IF('02_Actuals'!N11>='01_Assumptions'!N33,"Green",IF('02_Actuals'!N11>='01_Assumptions'!N33*(1-'01_Assumptions'!$E$18),"Amber","Red")),IF('01_Assumptions'!$D$18="L",IF('02_Actuals'!N11<='01_Assumptions'!N33,"Green",IF('02_Actuals'!N11<='01_Assumptions'!N33*(1+'01_Assumptions'!$E$18),"Amber","Red")),IF(ABS('02_Actuals'!N11/'01_Assumptions'!N33-1)<='01_Assumptions'!$F$18,"Green",IF(ABS('02_Actuals'!N11/'01_Assumptions'!N33-1)<='01_Assumptions'!$E$18,"Amber","Red")))))
B28: Scrap % | C28: =IF('01_Assumptions'!C34=0,"—",IF('01_Assumptions'!$D$19="H",IF('02_Actuals'!C12>='01_Assumptions'!C34,"Green",IF('02_Actuals'!C12>='01_Assumptions'!C34*(1-'01_Assumptions'!$E$19),"Amber","Red")),IF('01_Assumptions'!$D$19="L",IF('02_Actuals'!C12<='01_Assumptions'!C34,"Green",IF('02_Actuals'!C12<='01_Assumptions'!C34*(1+'01_Assumptions'!$E$19),"Amber","Red")),IF(ABS('02_Actuals'!C12/'01_Assumptions'!C34-1)<='01_Assumptions'!$F$19,"Green",IF(ABS('02_Actuals'!C12/'01_Assumptions'!C34-1)<='01_Assumptions'!$E$19,"Amber","Red"))))) | D28: =IF('01_Assumptions'!D34=0,"—",IF('01_Assumptions'!$D$19="H",IF('02_Actuals'!D12>='01_Assumptions'!D34,"Green",IF('02_Actuals'!D12>='01_Assumptions'!D34*(1-'01_Assumptions'!$E$19),"Amber","Red")),IF('01_Assumptions'!$D$19="L",IF('02_Actuals'!D12<='01_Assumptions'!D34,"Green",IF('02_Actuals'!D12<='01_Assumptions'!D34*(1+'01_Assumptions'!$E$19),"Amber","Red")),IF(ABS('02_Actuals'!D12/'01_Assumptions'!D34-1)<='01_Assumptions'!$F$19,"Green",IF(ABS('02_Actuals'!D12/'01_Assumptions'!D34-1)<='01_Assumptions'!$E$19,"Amber","Red"))))) | E28: =IF('01_Assumptions'!E34=0,"—",IF('01_Assumptions'!$D$19="H",IF('02_Actuals'!E12>='01_Assumptions'!E34,"Green",IF('02_Actuals'!E12>='01_Assumptions'!E34*(1-'01_Assumptions'!$E$19),"Amber","Red")),IF('01_Assumptions'!$D$19="L",IF('02_Actuals'!E12<='01_Assumptions'!E34,"Green",IF('02_Actuals'!E12<='01_Assumptions'!E34*(1+'01_Assumptions'!$E$19),"Amber","Red")),IF(ABS('02_Actuals'!E12/'01_Assumptions'!E34-1)<='01_Assumptions'!$F$19,"Green",IF(ABS('02_Actuals'!E12/'01_Assumptions'!E34-1)<='01_Assumptions'!$E$19,"Amber","Red"))))) | F28: =IF('01_Assumptions'!F34=0,"—",IF('01_Assumptions'!$D$19="H",IF('02_Actuals'!F12>='01_Assumptions'!F34,"Green",IF('02_Actuals'!F12>='01_Assumptions'!F34*(1-'01_Assumptions'!$E$19),"Amber","Red")),IF('01_Assumptions'!$D$19="L",IF('02_Actuals'!F12<='01_Assumptions'!F34,"Green",IF('02_Actuals'!F12<='01_Assumptions'!F34*(1+'01_Assumptions'!$E$19),"Amber","Red")),IF(ABS('02_Actuals'!F12/'01_Assumptions'!F34-1)<='01_Assumptions'!$F$19,"Green",IF(ABS('02_Actuals'!F12/'01_Assumptions'!F34-1)<='01_Assumptions'!$E$19,"Amber","Red"))))) | G28: =IF('01_Assumptions'!G34=0,"—",IF('01_Assumptions'!$D$19="H",IF('02_Actuals'!G12>='01_Assumptions'!G34,"Green",IF('02_Actuals'!G12>='01_Assumptions'!G34*(1-'01_Assumptions'!$E$19),"Amber","Red")),IF('01_Assumptions'!$D$19="L",IF('02_Actuals'!G12<='01_Assumptions'!G34,"Green",IF('02_Actuals'!G12<='01_Assumptions'!G34*(1+'01_Assumptions'!$E$19),"Amber","Red")),IF(ABS('02_Actuals'!G12/'01_Assumptions'!G34-1)<='01_Assumptions'!$F$19,"Green",IF(ABS('02_Actuals'!G12/'01_Assumptions'!G34-1)<='01_Assumptions'!$E$19,"Amber","Red"))))) | H28: =IF('01_Assumptions'!H34=0,"—",IF('01_Assumptions'!$D$19="H",IF('02_Actuals'!H12>='01_Assumptions'!H34,"Green",IF('02_Actuals'!H12>='01_Assumptions'!H34*(1-'01_Assumptions'!$E$19),"Amber","Red")),IF('01_Assumptions'!$D$19="L",IF('02_Actuals'!H12<='01_Assumptions'!H34,"Green",IF('02_Actuals'!H12<='01_Assumptions'!H34*(1+'01_Assumptions'!$E$19),"Amber","Red")),IF(ABS('02_Actuals'!H12/'01_Assumptions'!H34-1)<='01_Assumptions'!$F$19,"Green",IF(ABS('02_Actuals'!H12/'01_Assumptions'!H34-1)<='01_Assumptions'!$E$19,"Amber","Red"))))) | I28: =IF('01_Assumptions'!I34=0,"—",IF('01_Assumptions'!$D$19="H",IF('02_Actuals'!I12>='01_Assumptions'!I34,"Green",IF('02_Actuals'!I12>='01_Assumptions'!I34*(1-'01_Assumptions'!$E$19),"Amber","Red")),IF('01_Assumptions'!$D$19="L",IF('02_Actuals'!I12<='01_Assumptions'!I34,"Green",IF('02_Actuals'!I12<='01_Assumptions'!I34*(1+'01_Assumptions'!$E$19),"Amber","Red")),IF(ABS('02_Actuals'!I12/'01_Assumptions'!I34-1)<='01_Assumptions'!$F$19,"Green",IF(ABS('02_Actuals'!I12/'01_Assumptions'!I34-1)<='01_Assumptions'!$E$19,"Amber","Red"))))) | J28: =IF('01_Assumptions'!J34=0,"—",IF('01_Assumptions'!$D$19="H",IF('02_Actuals'!J12>='01_Assumptions'!J34,"Green",IF('02_Actuals'!J12>='01_Assumptions'!J34*(1-'01_Assumptions'!$E$19),"Amber","Red")),IF('01_Assumptions'!$D$19="L",IF('02_Actuals'!J12<='01_Assumptions'!J34,"Green",IF('02_Actuals'!J12<='01_Assumptions'!J34*(1+'01_Assumptions'!$E$19),"Amber","Red")),IF(ABS('02_Actuals'!J12/'01_Assumptions'!J34-1)<='01_Assumptions'!$F$19,"Green",IF(ABS('02_Actuals'!J12/'01_Assumptions'!J34-1)<='01_Assumptions'!$E$19,"Amber","Red"))))) | ... N28: =IF('01_Assumptions'!N34=0,"—",IF('01_Assumptions'!$D$19="H",IF('02_Actuals'!N12>='01_Assumptions'!N34,"Green",IF('02_Actuals'!N12>='01_Assumptions'!N34*(1-'01_Assumptions'!$E$19),"Amber","Red")),IF('01_Assumptions'!$D$19="L",IF('02_Actuals'!N12<='01_Assumptions'!N34,"Green",IF('02_Actuals'!N12<='01_Assumptions'!N34*(1+'01_Assumptions'!$E$19),"Amber","Red")),IF(ABS('02_Actuals'!N12/'01_Assumptions'!N34-1)<='01_Assumptions'!$F$19,"Green",IF(ABS('02_Actuals'!N12/'01_Assumptions'!N34-1)<='01_Assumptions'!$E$19,"Amber","Red")))))
B29: DSO | C29: =IF('01_Assumptions'!C35=0,"—",IF('01_Assumptions'!$D$20="H",IF('02_Actuals'!C13>='01_Assumptions'!C35,"Green",IF('02_Actuals'!C13>='01_Assumptions'!C35*(1-'01_Assumptions'!$E$20),"Amber","Red")),IF('01_Assumptions'!$D$20="L",IF('02_Actuals'!C13<='01_Assumptions'!C35,"Green",IF('02_Actuals'!C13<='01_Assumptions'!C35*(1+'01_Assumptions'!$E$20),"Amber","Red")),IF(ABS('02_Actuals'!C13/'01_Assumptions'!C35-1)<='01_Assumptions'!$F$20,"Green",IF(ABS('02_Actuals'!C13/'01_Assumptions'!C35-1)<='01_Assumptions'!$E$20,"Amber","Red"))))) | D29: =IF('01_Assumptions'!D35=0,"—",IF('01_Assumptions'!$D$20="H",IF('02_Actuals'!D13>='01_Assumptions'!D35,"Green",IF('02_Actuals'!D13>='01_Assumptions'!D35*(1-'01_Assumptions'!$E$20),"Amber","Red")),IF('01_Assumptions'!$D$20="L",IF('02_Actuals'!D13<='01_Assumptions'!D35,"Green",IF('02_Actuals'!D13<='01_Assumptions'!D35*(1+'01_Assumptions'!$E$20),"Amber","Red")),IF(ABS('02_Actuals'!D13/'01_Assumptions'!D35-1)<='01_Assumptions'!$F$20,"Green",IF(ABS('02_Actuals'!D13/'01_Assumptions'!D35-1)<='01_Assumptions'!$E$20,"Amber","Red"))))) | E29: =IF('01_Assumptions'!E35=0,"—",IF('01_Assumptions'!$D$20="H",IF('02_Actuals'!E13>='01_Assumptions'!E35,"Green",IF('02_Actuals'!E13>='01_Assumptions'!E35*(1-'01_Assumptions'!$E$20),"Amber","Red")),IF('01_Assumptions'!$D$20="L",IF('02_Actuals'!E13<='01_Assumptions'!E35,"Green",IF('02_Actuals'!E13<='01_Assumptions'!E35*(1+'01_Assumptions'!$E$20),"Amber","Red")),IF(ABS('02_Actuals'!E13/'01_Assumptions'!E35-1)<='01_Assumptions'!$F$20,"Green",IF(ABS('02_Actuals'!E13/'01_Assumptions'!E35-1)<='01_Assumptions'!$E$20,"Amber","Red"))))) | F29: =IF('01_Assumptions'!F35=0,"—",IF('01_Assumptions'!$D$20="H",IF('02_Actuals'!F13>='01_Assumptions'!F35,"Green",IF('02_Actuals'!F13>='01_Assumptions'!F35*(1-'01_Assumptions'!$E$20),"Amber","Red")),IF('01_Assumptions'!$D$20="L",IF('02_Actuals'!F13<='01_Assumptions'!F35,"Green",IF('02_Actuals'!F13<='01_Assumptions'!F35*(1+'01_Assumptions'!$E$20),"Amber","Red")),IF(ABS('02_Actuals'!F13/'01_Assumptions'!F35-1)<='01_Assumptions'!$F$20,"Green",IF(ABS('02_Actuals'!F13/'01_Assumptions'!F35-1)<='01_Assumptions'!$E$20,"Amber","Red"))))) | G29: =IF('01_Assumptions'!G35=0,"—",IF('01_Assumptions'!$D$20="H",IF('02_Actuals'!G13>='01_Assumptions'!G35,"Green",IF('02_Actuals'!G13>='01_Assumptions'!G35*(1-'01_Assumptions'!$E$20),"Amber","Red")),IF('01_Assumptions'!$D$20="L",IF('02_Actuals'!G13<='01_Assumptions'!G35,"Green",IF('02_Actuals'!G13<='01_Assumptions'!G35*(1+'01_Assumptions'!$E$20),"Amber","Red")),IF(ABS('02_Actuals'!G13/'01_Assumptions'!G35-1)<='01_Assumptions'!$F$20,"Green",IF(ABS('02_Actuals'!G13/'01_Assumptions'!G35-1)<='01_Assumptions'!$E$20,"Amber","Red"))))) | H29: =IF('01_Assumptions'!H35=0,"—",IF('01_Assumptions'!$D$20="H",IF('02_Actuals'!H13>='01_Assumptions'!H35,"Green",IF('02_Actuals'!H13>='01_Assumptions'!H35*(1-'01_Assumptions'!$E$20),"Amber","Red")),IF('01_Assumptions'!$D$20="L",IF('02_Actuals'!H13<='01_Assumptions'!H35,"Green",IF('02_Actuals'!H13<='01_Assumptions'!H35*(1+'01_Assumptions'!$E$20),"Amber","Red")),IF(ABS('02_Actuals'!H13/'01_Assumptions'!H35-1)<='01_Assumptions'!$F$20,"Green",IF(ABS('02_Actuals'!H13/'01_Assumptions'!H35-1)<='01_Assumptions'!$E$20,"Amber","Red"))))) | I29: =IF('01_Assumptions'!I35=0,"—",IF('01_Assumptions'!$D$20="H",IF('02_Actuals'!I13>='01_Assumptions'!I35,"Green",IF('02_Actuals'!I13>='01_Assumptions'!I35*(1-'01_Assumptions'!$E$20),"Amber","Red")),IF('01_Assumptions'!$D$20="L",IF('02_Actuals'!I13<='01_Assumptions'!I35,"Green",IF('02_Actuals'!I13<='01_Assumptions'!I35*(1+'01_Assumptions'!$E$20),"Amber","Red")),IF(ABS('02_Actuals'!I13/'01_Assumptions'!I35-1)<='01_Assumptions'!$F$20,"Green",IF(ABS('02_Actuals'!I13/'01_Assumptions'!I35-1)<='01_Assumptions'!$E$20,"Amber","Red"))))) | J29: =IF('01_Assumptions'!J35=0,"—",IF('01_Assumptions'!$D$20="H",IF('02_Actuals'!J13>='01_Assumptions'!J35,"Green",IF('02_Actuals'!J13>='01_Assumptions'!J35*(1-'01_Assumptions'!$E$20),"Amber","Red")),IF('01_Assumptions'!$D$20="L",IF('02_Actuals'!J13<='01_Assumptions'!J35,"Green",IF('02_Actuals'!J13<='01_Assumptions'!J35*(1+'01_Assumptions'!$E$20),"Amber","Red")),IF(ABS('02_Actuals'!J13/'01_Assumptions'!J35-1)<='01_Assumptions'!$F$20,"Green",IF(ABS('02_Actuals'!J13/'01_Assumptions'!J35-1)<='01_Assumptions'!$E$20,"Amber","Red"))))) | ... N29: =IF('01_Assumptions'!N35=0,"—",IF('01_Assumptions'!$D$20="H",IF('02_Actuals'!N13>='01_Assumptions'!N35,"Green",IF('02_Actuals'!N13>='01_Assumptions'!N35*(1-'01_Assumptions'!$E$20),"Amber","Red")),IF('01_Assumptions'!$D$20="L",IF('02_Actuals'!N13<='01_Assumptions'!N35,"Green",IF('02_Actuals'!N13<='01_Assumptions'!N35*(1+'01_Assumptions'!$E$20),"Amber","Red")),IF(ABS('02_Actuals'!N13/'01_Assumptions'!N35-1)<='01_Assumptions'!$F$20,"Green",IF(ABS('02_Actuals'!N13/'01_Assumptions'!N35-1)<='01_Assumptions'!$E$20,"Amber","Red")))))
